Workbook

Sheet Instrumentation Cables
A1: Instrument And Wires List
A2: TAG NO | B2: Controls Notes | C2: P&IDs Notes | D2: Voltage | E2: INTRINSICALLY SAFE | F2: SIGNAL | G2: CONNECTION | H2: Cable Designation | I2: Cable Qty | J2: Conduit | K2: Conduit Branch | M2: IN STOCK CABLES
A3: CBL 811 | E3: NO | F3: DIGITAL CONTACT | G3: 2 wire | H3: Alan16 | I3: 2 | J3: CUSTOMER DCS - LCP-1 | M3: Company | N3: Designation | O3: Size | P3: Conductors | Q3: Shield | R3: Voltage | S3: Type | T3: Nom Diameter
A4: CBL 813 | E4: NO | F4: DIGITAL CONTACT | G4: 2 wire | H4: Alan16 | I4: 2 | J4: CUSTOMER DCS - LCP-1 | M4: Dekoron | N4: Dek2C | O4: 16 AWG | P4: 2 C | Q4: Yes | R4: 600 V | S4: TC-ER | T4: 0.287
A5: XL-1 | E5: NO | F5: DIGITAL CONTACT | G5: 4 pair shielded | H5: Dek2C | I5: 1 | J5: CUSTOMER MCC - LCP-1 | M5: Dekoron | N5: Dek3C | O5: 16 AWG | P5: 3 C | Q5: Yes | R5: 600 V | S5: TC-ER | T5: 0.325
A6: XA-1 | E6: NO | F6: DIGITAL CONTACT | G6: … | H6: Dek2C | I6: 1 | J6: CUSTOMER MCC - LCP-1 | M6: Dekoron | N6: Dek4C | O6: 16 AWG | P6: 4 C | Q6: Yes | R6: 600 V | S6: TC-ER | T6: 0.355
A7: XL-3 | E7: NO | F7: DIGITAL CONTACT | G7: … | H7: Dek2C | I7: 1 | J7: CUSTOMER MCC - LCP-1 | M7: Alan Wire | N7: Alan16 | O7: 16 AWG | P7: 1 C | Q7: No | R7: 600 V | S7: TFFN oil gas | T7: 0.095
A8: XL-4 | E8: NO | F8: DIGITAL CONTACT | G8: … | H8: Dek2C | I8: 1 | J8: CUSTOMER MCC - LCP-1 | M8: Alan Wire | N8: Alan10 | O8: 10 AWG | P8: 1 C | Q8: No | R8: 600 V | S8: TC-ER | T8: 0.16
A9: XY-1 | E9: NO | F9: DIGITAL CONTACT | G9: 2 wire | H9: Alan16 | I9: 2 | J9: CUSTOMER MCC - LCP-1 | M9: Alan Wire | N9: Alan6 | O9: 6 AWG | P9: 1 C | Q9: No | R9: 600 V | S9: TC-ER
A10: XY-3 | E10: NO | F10: DIGITAL CONTACT | G10: 2 wire | H10: Alan16 | I10: 2 | J10: CUSTOMER MCC - LCP-1 | M10: Advanced Digital Cable | N10: Advanced14 | O10: 14 AWG | P10: 3 C | Q10: No | R10: 600 V | S10: TC-ER
A11: XY-4 | E11: NO | F11: DIGITAL CONTACT | G11: 2 wire | H11: Alan16 | I11: 2 | J11: CUSTOMER MCC - LCP-1 | M11: Reynolds | N11: Motor12 | O11: 18 AWG | P11: 12 C | Q11: No | R11: 600 V | S11: TC-ER | T11: 0.43
A12: II-1 | E12: NO | F12: 4-20 mA | G12: 2 wire shielded | H12: Dek2C | I12: 1 | J12: CUSTOMER MCC - LCP-1 | M12: Reynolds | N12: Motor12Sh | O12: 18 AWG | P12: 12 C | Q12: Yes | R12: 600 V | S12: TC-ER | T12: 0.51
A13: XT-7A | E13: NO | F13: 4-20 mA | G13: 2 wire shielded | H13: Dek2C | I13: 1 | J13: CUSTOMER MCC - LCP-1
A14: RUN INTERLOCK | E14: NO | F14: DIGITAL CONTACT | G14: 2 wire shielded | H14: Dek2C | I14: 1 | J14: FROM CUSTOMER - LCP-1
A15: VSH-1 | E15: NO | F15: 4-20 mA | G15: 2 wire | H15: Alan16 | I15: 2 | J15: FROM CUSTOMER - LCP-1
A16: ZE-1A | E16: YES | F16: 4-20 mA | G16: 3 wire shielded | H16: Dek3C | I16: 1 | J16: GREEN | K16: G2
A17: ZE-1B | E17: YES | F17: 4-20 mA | G17: 3 wire shielded | H17: Dek3C | I17: 1 | J17: GREEN | K17: G1
A18: PCV-201 | E18: YES | F18: 4-20 mA | G18: 2 wire shielded | H18: Dek2C | I18: 1 | J18: GREEN | K18: G2
A19: TCV-201 | E19: YES | F19: 4-20 mA | G19: 2 wire shielded | H19: Dek2C | I19: 1 | J19: GREEN | K19: G2
A20: ZSO-071 | E20: NO | F20: 4-20 mA | G20: 2 wire | H20: Alan16 | I20: 2 | J20: RED | K20: R3
A21: ZSC-071 | E21: NO | F21: 4-20 mA | G21: 2 wire | H21: Alan16 | I21: 2 | J21: RED | K21: R3
A22: ZSO-151 | E22: NO | F22: 4-20 mA | G22: 2 wire | H22: Alan16 | I22: 2 | J22: RED | K22: R3
A23: ZSC-151 | E23: NO | F23: 4-20 mA | G23: 2 wire | H23: Alan16 | I23: 2 | J23: RED | K23: R3
A24: ZSO-201 | E24: NO | F24: 4-20 mA | G24: 2 wire | H24: Alan16 | I24: 2 | J24: RED | K24: R4
A25: ZSC-201 | E25: NO | F25: 4-20 mA | G25: 2 wire | H25: Alan16 | I25: 2 | J25: RED | K25: R4 | P25: Minimum required Conduit Size
A26: SV-071 | E26: NO | F26: 4-20 mA | G26: 2 wire | H26: Alan16 | I26: 2 | J26: RED | K26: R3 | M26: Conduit | N26: Number of Cables | O26: Sum of Cross Sectional Areas | P26: Rigid Metal Conduit | Q26: Liquidtight Flexible Nonmetallic Conduit | R26: Flexible Metal Conduit | S26: Chosen Size
A27: SV-201 | E27: NO | F27: 4-20 mA | G27: 2 wire | H27: Alan16 | I27: 2 | J27: RED | K27: R4 | M27: {=IFERROR(INDEX(_xlfn._xlws.SORT(_xlfn.UNIQUE(_xlfn._xlws.FILTER(_xlfn.VSTACK(Table3[[Conduit ]],Table3[Conduit Branch]),_xlfn.VSTACK(Table3[[Conduit ]],Table3[Conduit Branch])<>""))),ROWS($M$27:M27)),"")} -> B1 | N27: {=IF($M27="","",_xlfn.LET(_xlpm.item,$M27,_xlpm.qty,IF(Table3[Cable Qty]="",1,Table3[Cable Qty]),SUMPRODUCT(--(((Table3[[Conduit ]]=_xlpm.item)+(Table3[Conduit Branch]=_xlpm.item))>0),_xlpm.qty)))} -> 2 | O27: {=IF($M27="","",_xlfn.LET(_xlpm.item,$M27,_xlpm.diameters,_xlfn.XLOOKUP(Table3[Cable Designation]&"",Table6[Designation]&"",Table6[Nom Diameter],0),_xlpm.qty,IFERROR(Table3[Cable Qty],1),SUMPRODUCT(((Table3[[Conduit ]]=_xlpm.item)+(Table3[Conduit Branch]=_xlpm.item))*_xlpm.qty*PI()*(_xlpm.diameters/2)^2)))} -> 0 | P27: {=IF($M27="","",_xlfn.LET(_xlpm.area,$O27,_xlpm.cnt,$N27,_xlpm.sizes,'Conduit Tables'!$C$4:$C$16,_xlpm.cap,IF(_xlpm.cnt=1,'Conduit Tables'!$I$4:$I$16,IF(_xlpm.cnt=2,'Conduit Tables'!$K$4:$K$16,'Conduit Tables'!$E$4:$E$16)),_xlfn.XLOOKUP(TRUE,IF(ISNUMBER(_xlpm.cap),_xlpm.cap>=_xlpm.area,FALSE),_xlpm.sizes,"No size")))} -> ½ | Q27: {=IF($M27="","",_xlfn.LET(_xlpm.area,$O27,_xlpm.cnt,$N27,_xlpm.sizes,'Conduit Tables'!$C$20:$C$26,_xlpm.cap,IF(_xlpm.cnt=1,'Conduit Tables'!$I$20:$I$26,IF(_xlpm.cnt=2,'Conduit Tables'!$K$20:$K$26,'Conduit Tables'!$E$20:$E$26)),_xlfn.XLOOKUP(TRUE,IF(ISNUMBER(_xlpm.cap),_xlpm.cap>=_xlpm.area,FALSE),_xlpm.sizes,"No size")))} -> 3/8 | R27: {=IF($M27="","",_xlfn.LET(_xlpm.area,$O27,_xlpm.cnt,$N27,_xlpm.sizes,'Conduit Tables'!$C$30:$C$38,_xlpm.cap,IF(_xlpm.cnt=1,'Conduit Tables'!$I$30:$I$38,IF(_xlpm.cnt=2,'Conduit Tables'!$K$30:$K$38,'Conduit Tables'!$E$30:$E$38)),_xlfn.XLOOKUP(TRUE,IF(ISNUMBER(_xlpm.cap),_xlpm.cap>=_xlpm.area,FALSE),_xlpm.sizes,"No size")))} -> 3/8 | S27: 3/4
A28: SV-151 | E28: NO | F28: 4-20 mA | G28: 2 wire | H28: Alan16 | I28: 2 | J28: RED | K28: R3 | M28: {=IFERROR(INDEX(_xlfn._xlws.SORT(_xlfn.UNIQUE(_xlfn._xlws.FILTER(_xlfn.VSTACK(Table3[[Conduit ]],Table3[Conduit Branch]),_xlfn.VSTACK(Table3[[Conduit ]],Table3[Conduit Branch])<>""))),ROWS($M$27:M28)),"")} -> B2 | N28: {=IF($M28="","",_xlfn.LET(_xlpm.item,$M28,_xlpm.qty,IF(Table3[Cable Qty]="",1,Table3[Cable Qty]),SUMPRODUCT(--(((Table3[[Conduit ]]=_xlpm.item)+(Table3[Conduit Branch]=_xlpm.item))>0),_xlpm.qty)))} -> 2 | O28: {=IF($M28="","",_xlfn.LET(_xlpm.item,$M28,_xlpm.diameters,_xlfn.XLOOKUP(Table3[Cable Designation]&"",Table6[Designation]&"",Table6[Nom Diameter],0),_xlpm.qty,IFERROR(Table3[Cable Qty],1),SUMPRODUCT(((Table3[[Conduit ]]=_xlpm.item)+(Table3[Conduit Branch]=_xlpm.item))*_xlpm.qty*PI()*(_xlpm.diameters/2)^2)))} -> 0 | P28: {=IF($M28="","",_xlfn.LET(_xlpm.area,$O28,_xlpm.cnt,$N28,_xlpm.sizes,'Conduit Tables'!$C$4:$C$16,_xlpm.cap,IF(_xlpm.cnt=1,'Conduit Tables'!$I$4:$I$16,IF(_xlpm.cnt=2,'Conduit Tables'!$K$4:$K$16,'Conduit Tables'!$E$4:$E$16)),_xlfn.XLOOKUP(TRUE,IF(ISNUMBER(_xlpm.cap),_xlpm.cap>=_xlpm.area,FALSE),_xlpm.sizes,"No size")))} -> ½ | Q28: {=IF($M28="","",_xlfn.LET(_xlpm.area,$O28,_xlpm.cnt,$N28,_xlpm.sizes,'Conduit Tables'!$C$20:$C$26,_xlpm.cap,IF(_xlpm.cnt=1,'Conduit Tables'!$I$20:$I$26,IF(_xlpm.cnt=2,'Conduit Tables'!$K$20:$K$26,'Conduit Tables'!$E$20:$E$26)),_xlfn.XLOOKUP(TRUE,IF(ISNUMBER(_xlpm.cap),_xlpm.cap>=_xlpm.area,FALSE),_xlpm.sizes,"No size")))} -> 3/8 | R28: {=IF($M28="","",_xlfn.LET(_xlpm.area,$O28,_xlpm.cnt,$N28,_xlpm.sizes,'Conduit Tables'!$C$30:$C$38,_xlpm.cap,IF(_xlpm.cnt=1,'Conduit Tables'!$I$30:$I$38,IF(_xlpm.cnt=2,'Conduit Tables'!$K$30:$K$38,'Conduit Tables'!$E$30:$E$38)),_xlfn.XLOOKUP(TRUE,IF(ISNUMBER(_xlpm.cap),_xlpm.cap>=_xlpm.area,FALSE),_xlpm.sizes,"No size")))} -> 3/8 | S28: 3/4
A29: SV-075 | E29: NO | F29: 4-20 mA | G29: 2 wire | H29: Alan16 | I29: 2 | J29: RED | K29: R2 | M29: {=IFERROR(INDEX(_xlfn._xlws.SORT(_xlfn.UNIQUE(_xlfn._xlws.FILTER(_xlfn.VSTACK(Table3[[Conduit ]],Table3[Conduit Branch]),_xlfn.VSTACK(Table3[[Conduit ]],Table3[Conduit Branch])<>""))),ROWS($M$27:M29)),"")} -> BLUE | N29: {=IF($M29="","",_xlfn.LET(_xlpm.item,$M29,_xlpm.qty,IF(Table3[Cable Qty]="",1,Table3[Cable Qty]),SUMPRODUCT(--(((Table3[[Conduit ]]=_xlpm.item)+(Table3[Conduit Branch]=_xlpm.item))>0),_xlpm.qty)))} -> 4 | O29: {=IF($M29="","",_xlfn.LET(_xlpm.item,$M29,_xlpm.diameters,_xlfn.XLOOKUP(Table3[Cable Designation]&"",Table6[Designation]&"",Table6[Nom Diameter],0),_xlpm.qty,IFERROR(Table3[Cable Qty],1),SUMPRODUCT(((Table3[[Conduit ]]=_xlpm.item)+(Table3[Conduit Branch]=_xlpm.item))*_xlpm.qty*PI()*(_xlpm.diameters/2)^2)))} -> 0 | P29: {=IF($M29="","",_xlfn.LET(_xlpm.area,$O29,_xlpm.cnt,$N29,_xlpm.sizes,'Conduit Tables'!$C$4:$C$16,_xlpm.cap,IF(_xlpm.cnt=1,'Conduit Tables'!$I$4:$I$16,IF(_xlpm.cnt=2,'Conduit Tables'!$K$4:$K$16,'Conduit Tables'!$E$4:$E$16)),_xlfn.XLOOKUP(TRUE,IF(ISNUMBER(_xlpm.cap),_xlpm.cap>=_xlpm.area,FALSE),_xlpm.sizes,"No size")))} -> ½ | Q29: {=IF($M29="","",_xlfn.LET(_xlpm.area,$O29,_xlpm.cnt,$N29,_xlpm.sizes,'Conduit Tables'!$C$20:$C$26,_xlpm.cap,IF(_xlpm.cnt=1,'Conduit Tables'!$I$20:$I$26,IF(_xlpm.cnt=2,'Conduit Tables'!$K$20:$K$26,'Conduit Tables'!$E$20:$E$26)),_xlfn.XLOOKUP(TRUE,IF(ISNUMBER(_xlpm.cap),_xlpm.cap>=_xlpm.area,FALSE),_xlpm.sizes,"No size")))} -> 3/8 | R29: {=IF($M29="","",_xlfn.LET(_xlpm.area,$O29,_xlpm.cnt,$N29,_xlpm.sizes,'Conduit Tables'!$C$30:$C$38,_xlpm.cap,IF(_xlpm.cnt=1,'Conduit Tables'!$I$30:$I$38,IF(_xlpm.cnt=2,'Conduit Tables'!$K$30:$K$38,'Conduit Tables'!$E$30:$E$38)),_xlfn.XLOOKUP(TRUE,IF(ISNUMBER(_xlpm.cap),_xlpm.cap>=_xlpm.area,FALSE),_xlpm.sizes,"No size")))} -> 3/8 | S29: 3/4
A30: PT-1 | E30: NO | F30: 4-20 mA | G30: 2 wire shielded | H30: Dek2C | I30: 1 | J30: RED | K30: R3 | M30: {=IFERROR(INDEX(_xlfn._xlws.SORT(_xlfn.UNIQUE(_xlfn._xlws.FILTER(_xlfn.VSTACK(Table3[[Conduit ]],Table3[Conduit Branch]),_xlfn.VSTACK(Table3[[Conduit ]],Table3[Conduit Branch])<>""))),ROWS($M$27:M30)),"")} -> CUSTOMER DCS - LCP-1 | N30: {=IF($M30="","",_xlfn.LET(_xlpm.item,$M30,_xlpm.qty,IF(Table3[Cable Qty]="",1,Table3[Cable Qty]),SUMPRODUCT(--(((Table3[[Conduit ]]=_xlpm.item)+(Table3[Conduit Branch]=_xlpm.item))>0),_xlpm.qty)))} -> 4 | O30: {=IF($M30="","",_xlfn.LET(_xlpm.item,$M30,_xlpm.diameters,_xlfn.XLOOKUP(Table3[Cable Designation]&"",Table6[Designation]&"",Table6[Nom Diameter],0),_xlpm.qty,IFERROR(Table3[Cable Qty],1),SUMPRODUCT(((Table3[[Conduit ]]=_xlpm.item)+(Table3[Conduit Branch]=_xlpm.item))*_xlpm.qty*PI()*(_xlpm.diameters/2)^2)))} -> 0.028352874 | P30: {=IF($M30="","",_xlfn.LET(_xlpm.area,$O30,_xlpm.cnt,$N30,_xlpm.sizes,'Conduit Tables'!$C$4:$C$16,_xlpm.cap,IF(_xlpm.cnt=1,'Conduit Tables'!$I$4:$I$16,IF(_xlpm.cnt=2,'Conduit Tables'!$K$4:$K$16,'Conduit Tables'!$E$4:$E$16)),_xlfn.XLOOKUP(TRUE,IF(ISNUMBER(_xlpm.cap),_xlpm.cap>=_xlpm.area,FALSE),_xlpm.sizes,"No size")))} -> ½ | Q30: {=IF($M30="","",_xlfn.LET(_xlpm.area,$O30,_xlpm.cnt,$N30,_xlpm.sizes,'Conduit Tables'!$C$20:$C$26,_xlpm.cap,IF(_xlpm.cnt=1,'Conduit Tables'!$I$20:$I$26,IF(_xlpm.cnt=2,'Conduit Tables'!$K$20:$K$26,'Conduit Tables'!$E$20:$E$26)),_xlfn.XLOOKUP(TRUE,IF(ISNUMBER(_xlpm.cap),_xlpm.cap>=_xlpm.area,FALSE),_xlpm.sizes,"No size")))} -> 3/8 | R30: {=IF($M30="","",_xlfn.LET(_xlpm.area,$O30,_xlpm.cnt,$N30,_xlpm.sizes,'Conduit Tables'!$C$30:$C$38,_xlpm.cap,IF(_xlpm.cnt=1,'Conduit Tables'!$I$30:$I$38,IF(_xlpm.cnt=2,'Conduit Tables'!$K$30:$K$38,'Conduit Tables'!$E$30:$E$38)),_xlfn.XLOOKUP(TRUE,IF(ISNUMBER(_xlpm.cap),_xlpm.cap>=_xlpm.area,FALSE),_xlpm.sizes,"No size")))} -> 3/8
A31: PT-3 | E31: NO | F31: 4-20 mA | G31: 2 wire shielded | H31: Dek2C | I31: 1 | J31: RED | K31: R3 | M31: {=IFERROR(INDEX(_xlfn._xlws.SORT(_xlfn.UNIQUE(_xlfn._xlws.FILTER(_xlfn.VSTACK(Table3[[Conduit ]],Table3[Conduit Branch]),_xlfn.VSTACK(Table3[[Conduit ]],Table3[Conduit Branch])<>""))),ROWS($M$27:M31)),"")} -> CUSTOMER MCC - LCP-1 | N31: {=IF($M31="","",_xlfn.LET(_xlpm.item,$M31,_xlpm.qty,IF(Table3[Cable Qty]="",1,Table3[Cable Qty]),SUMPRODUCT(--(((Table3[[Conduit ]]=_xlpm.item)+(Table3[Conduit Branch]=_xlpm.item))>0),_xlpm.qty)))} -> 12 | O31: {=IF($M31="","",_xlfn.LET(_xlpm.item,$M31,_xlpm.diameters,_xlfn.XLOOKUP(Table3[Cable Designation]&"",Table6[Designation]&"",Table6[Nom Diameter],0),_xlpm.qty,IFERROR(Table3[Cable Qty],1),SUMPRODUCT(((Table3[[Conduit ]]=_xlpm.item)+(Table3[Conduit Branch]=_xlpm.item))*_xlpm.qty*PI()*(_xlpm.diameters/2)^2)))} -> 0.43068408 | P31: {=IF($M31="","",_xlfn.LET(_xlpm.area,$O31,_xlpm.cnt,$N31,_xlpm.sizes,'Conduit Tables'!$C$4:$C$16,_xlpm.cap,IF(_xlpm.cnt=1,'Conduit Tables'!$I$4:$I$16,IF(_xlpm.cnt=2,'Conduit Tables'!$K$4:$K$16,'Conduit Tables'!$E$4:$E$16)),_xlfn.XLOOKUP(TRUE,IF(ISNUMBER(_xlpm.cap),_xlpm.cap>=_xlpm.area,FALSE),_xlpm.sizes,"No size")))} -> 1¼ | Q31: {=IF($M31="","",_xlfn.LET(_xlpm.area,$O31,_xlpm.cnt,$N31,_xlpm.sizes,'Conduit Tables'!$C$20:$C$26,_xlpm.cap,IF(_xlpm.cnt=1,'Conduit Tables'!$I$20:$I$26,IF(_xlpm.cnt=2,'Conduit Tables'!$K$20:$K$26,'Conduit Tables'!$E$20:$E$26)),_xlfn.XLOOKUP(TRUE,IF(ISNUMBER(_xlpm.cap),_xlpm.cap>=_xlpm.area,FALSE),_xlpm.sizes,"No size")))} -> 1 1/4 | R31: {=IF($M31="","",_xlfn.LET(_xlpm.area,$O31,_xlpm.cnt,$N31,_xlpm.sizes,'Conduit Tables'!$C$30:$C$38,_xlpm.cap,IF(_xlpm.cnt=1,'Conduit Tables'!$I$30:$I$38,IF(_xlpm.cnt=2,'Conduit Tables'!$K$30:$K$38,'Conduit Tables'!$E$30:$E$38)),_xlfn.XLOOKUP(TRUE,IF(ISNUMBER(_xlpm.cap),_xlpm.cap>=_xlpm.area,FALSE),_xlpm.sizes,"No size")))} -> 3/4
A32: PT-6 | E32: NO | F32: 4-20 mA | G32: 2 wire shielded | H32: Dek2C | I32: 1 | J32: YELLOW | K32: Y1 | M32: {=IFERROR(INDEX(_xlfn._xlws.SORT(_xlfn.UNIQUE(_xlfn._xlws.FILTER(_xlfn.VSTACK(Table3[[Conduit ]],Table3[Conduit Branch]),_xlfn.VSTACK(Table3[[Conduit ]],Table3[Conduit Branch])<>""))),ROWS($M$27:M32)),"")} -> FROM CUSTOMER - LCP-1 | N32: {=IF($M32="","",_xlfn.LET(_xlpm.item,$M32,_xlpm.qty,IF(Table3[Cable Qty]="",1,Table3[Cable Qty]),SUMPRODUCT(--(((Table3[[Conduit ]]=_xlpm.item)+(Table3[Conduit Branch]=_xlpm.item))>0),_xlpm.qty)))} -> 3 | O32: {=IF($M32="","",_xlfn.LET(_xlpm.item,$M32,_xlpm.diameters,_xlfn.XLOOKUP(Table3[Cable Designation]&"",Table6[Designation]&"",Table6[Nom Diameter],0),_xlpm.qty,IFERROR(Table3[Cable Qty],1),SUMPRODUCT(((Table3[[Conduit ]]=_xlpm.item)+(Table3[Conduit Branch]=_xlpm.item))*_xlpm.qty*PI()*(_xlpm.diameters/2)^2)))} -> 0.078868898 | P32: {=IF($M32="","",_xlfn.LET(_xlpm.area,$O32,_xlpm.cnt,$N32,_xlpm.sizes,'Conduit Tables'!$C$4:$C$16,_xlpm.cap,IF(_xlpm.cnt=1,'Conduit Tables'!$I$4:$I$16,IF(_xlpm.cnt=2,'Conduit Tables'!$K$4:$K$16,'Conduit Tables'!$E$4:$E$16)),_xlfn.XLOOKUP(TRUE,IF(ISNUMBER(_xlpm.cap),_xlpm.cap>=_xlpm.area,FALSE),_xlpm.sizes,"No size")))} -> ½ | Q32: {=IF($M32="","",_xlfn.LET(_xlpm.area,$O32,_xlpm.cnt,$N32,_xlpm.sizes,'Conduit Tables'!$C$20:$C$26,_xlpm.cap,IF(_xlpm.cnt=1,'Conduit Tables'!$I$20:$I$26,IF(_xlpm.cnt=2,'Conduit Tables'!$K$20:$K$26,'Conduit Tables'!$E$20:$E$26)),_xlfn.XLOOKUP(TRUE,IF(ISNUMBER(_xlpm.cap),_xlpm.cap>=_xlpm.area,FALSE),_xlpm.sizes,"No size")))} -> 1/2 | R32: {=IF($M32="","",_xlfn.LET(_xlpm.area,$O32,_xlpm.cnt,$N32,_xlpm.sizes,'Conduit Tables'!$C$30:$C$38,_xlpm.cap,IF(_xlpm.cnt=1,'Conduit Tables'!$I$30:$I$38,IF(_xlpm.cnt=2,'Conduit Tables'!$K$30:$K$38,'Conduit Tables'!$E$30:$E$38)),_xlfn.XLOOKUP(TRUE,IF(ISNUMBER(_xlpm.cap),_xlpm.cap>=_xlpm.area,FALSE),_xlpm.sizes,"No size")))} -> 3/8
A33: VT-1 | E33: NO | F33: 4-20 mA | G33: 2 wire shielded | H33: Dek2C | I33: 1 | J33: RED | K33: R2 | M33: {=IFERROR(INDEX(_xlfn._xlws.SORT(_xlfn.UNIQUE(_xlfn._xlws.FILTER(_xlfn.VSTACK(Table3[[Conduit ]],Table3[Conduit Branch]),_xlfn.VSTACK(Table3[[Conduit ]],Table3[Conduit Branch])<>""))),ROWS($M$27:M33)),"")} -> G1 | N33: {=IF($M33="","",_xlfn.LET(_xlpm.item,$M33,_xlpm.qty,IF(Table3[Cable Qty]="",1,Table3[Cable Qty]),SUMPRODUCT(--(((Table3[[Conduit ]]=_xlpm.item)+(Table3[Conduit Branch]=_xlpm.item))>0),_xlpm.qty)))} -> 1 | O33: {=IF($M33="","",_xlfn.LET(_xlpm.item,$M33,_xlpm.diameters,_xlfn.XLOOKUP(Table3[Cable Designation]&"",Table6[Designation]&"",Table6[Nom Diameter],0),_xlpm.qty,IFERROR(Table3[Cable Qty],1),SUMPRODUCT(((Table3[[Conduit ]]=_xlpm.item)+(Table3[Conduit Branch]=_xlpm.item))*_xlpm.qty*PI()*(_xlpm.diameters/2)^2)))} -> 0.082957681 | P33: {=IF($M33="","",_xlfn.LET(_xlpm.area,$O33,_xlpm.cnt,$N33,_xlpm.sizes,'Conduit Tables'!$C$4:$C$16,_xlpm.cap,IF(_xlpm.cnt=1,'Conduit Tables'!$I$4:$I$16,IF(_xlpm.cnt=2,'Conduit Tables'!$K$4:$K$16,'Conduit Tables'!$E$4:$E$16)),_xlfn.XLOOKUP(TRUE,IF(ISNUMBER(_xlpm.cap),_xlpm.cap>=_xlpm.area,FALSE),_xlpm.sizes,"No size")))} -> ½ | Q33: {=IF($M33="","",_xlfn.LET(_xlpm.area,$O33,_xlpm.cnt,$N33,_xlpm.sizes,'Conduit Tables'!$C$20:$C$26,_xlpm.cap,IF(_xlpm.cnt=1,'Conduit Tables'!$I$20:$I$26,IF(_xlpm.cnt=2,'Conduit Tables'!$K$20:$K$26,'Conduit Tables'!$E$20:$E$26)),_xlfn.XLOOKUP(TRUE,IF(ISNUMBER(_xlpm.cap),_xlpm.cap>=_xlpm.area,FALSE),_xlpm.sizes,"No size")))} -> 3/8 | R33: {=IF($M33="","",_xlfn.LET(_xlpm.area,$O33,_xlpm.cnt,$N33,_xlpm.sizes,'Conduit Tables'!$C$30:$C$38,_xlpm.cap,IF(_xlpm.cnt=1,'Conduit Tables'!$I$30:$I$38,IF(_xlpm.cnt=2,'Conduit Tables'!$K$30:$K$38,'Conduit Tables'!$E$30:$E$38)),_xlfn.XLOOKUP(TRUE,IF(ISNUMBER(_xlpm.cap),_xlpm.cap>=_xlpm.area,FALSE),_xlpm.sizes,"No size")))} -> 3/8 | S33: 3/4
A34: VT-2 | E34: NO | F34: 4-20 mA | G34: 2 wire shielded | H34: Dek2C | I34: 1 | J34: RED | K34: R1 | M34: {=IFERROR(INDEX(_xlfn._xlws.SORT(_xlfn.UNIQUE(_xlfn._xlws.FILTER(_xlfn.VSTACK(Table3[[Conduit ]],Table3[Conduit Branch]),_xlfn.VSTACK(Table3[[Conduit ]],Table3[Conduit Branch])<>""))),ROWS($M$27:M34)),"")} -> G2 | N34: {=IF($M34="","",_xlfn.LET(_xlpm.item,$M34,_xlpm.qty,IF(Table3[Cable Qty]="",1,Table3[Cable Qty]),SUMPRODUCT(--(((Table3[[Conduit ]]=_xlpm.item)+(Table3[Conduit Branch]=_xlpm.item))>0),_xlpm.qty)))} -> 3 | O34: {=IF($M34="","",_xlfn.LET(_xlpm.item,$M34,_xlpm.diameters,_xlfn.XLOOKUP(Table3[Cable Designation]&"",Table6[Designation]&"",Table6[Nom Diameter],0),_xlpm.qty,IFERROR(Table3[Cable Qty],1),SUMPRODUCT(((Table3[[Conduit ]]=_xlpm.item)+(Table3[Conduit Branch]=_xlpm.item))*_xlpm.qty*PI()*(_xlpm.diameters/2)^2)))} -> 0.2123426 | P34: {=IF($M34="","",_xlfn.LET(_xlpm.area,$O34,_xlpm.cnt,$N34,_xlpm.sizes,'Conduit Tables'!$C$4:$C$16,_xlpm.cap,IF(_xlpm.cnt=1,'Conduit Tables'!$I$4:$I$16,IF(_xlpm.cnt=2,'Conduit Tables'!$K$4:$K$16,'Conduit Tables'!$E$4:$E$16)),_xlfn.XLOOKUP(TRUE,IF(ISNUMBER(_xlpm.cap),_xlpm.cap>=_xlpm.area,FALSE),_xlpm.sizes,"No size")))} -> ¾ | Q34: {=IF($M34="","",_xlfn.LET(_xlpm.area,$O34,_xlpm.cnt,$N34,_xlpm.sizes,'Conduit Tables'!$C$20:$C$26,_xlpm.cap,IF(_xlpm.cnt=1,'Conduit Tables'!$I$20:$I$26,IF(_xlpm.cnt=2,'Conduit Tables'!$K$20:$K$26,'Conduit Tables'!$E$20:$E$26)),_xlfn.XLOOKUP(TRUE,IF(ISNUMBER(_xlpm.cap),_xlpm.cap>=_xlpm.area,FALSE),_xlpm.sizes,"No size")))} -> 3/4 | R34: {=IF($M34="","",_xlfn.LET(_xlpm.area,$O34,_xlpm.cnt,$N34,_xlpm.sizes,'Conduit Tables'!$C$30:$C$38,_xlpm.cap,IF(_xlpm.cnt=1,'Conduit Tables'!$I$30:$I$38,IF(_xlpm.cnt=2,'Conduit Tables'!$K$30:$K$38,'Conduit Tables'!$E$30:$E$38)),_xlfn.XLOOKUP(TRUE,IF(ISNUMBER(_xlpm.cap),_xlpm.cap>=_xlpm.area,FALSE),_xlpm.sizes,"No size")))} -> 1/2 | S34: 3/4
A35: TT-1 | E35: NO | F35: 4-20 mA | G35: 2 wire shielded | H35: Dek2C | I35: 1 | J35: RED | K35: R3 | M35: {=IFERROR(INDEX(_xlfn._xlws.SORT(_xlfn.UNIQUE(_xlfn._xlws.FILTER(_xlfn.VSTACK(Table3[[Conduit ]],Table3[Conduit Branch]),_xlfn.VSTACK(Table3[[Conduit ]],Table3[Conduit Branch])<>""))),ROWS($M$27:M35)),"")} -> GREEN | N35: {=IF($M35="","",_xlfn.LET(_xlpm.item,$M35,_xlpm.qty,IF(Table3[Cable Qty]="",1,Table3[Cable Qty]),SUMPRODUCT(--(((Table3[[Conduit ]]=_xlpm.item)+(Table3[Conduit Branch]=_xlpm.item))>0),_xlpm.qty)))} -> 4 | O35: {=IF($M35="","",_xlfn.LET(_xlpm.item,$M35,_xlpm.diameters,_xlfn.XLOOKUP(Table3[Cable Designation]&"",Table6[Designation]&"",Table6[Nom Diameter],0),_xlpm.qty,IFERROR(Table3[Cable Qty],1),SUMPRODUCT(((Table3[[Conduit ]]=_xlpm.item)+(Table3[Conduit Branch]=_xlpm.item))*_xlpm.qty*PI()*(_xlpm.diameters/2)^2)))} -> 0.29530028 | P35: {=IF($M35="","",_xlfn.LET(_xlpm.area,$O35,_xlpm.cnt,$N35,_xlpm.sizes,'Conduit Tables'!$C$4:$C$16,_xlpm.cap,IF(_xlpm.cnt=1,'Conduit Tables'!$I$4:$I$16,IF(_xlpm.cnt=2,'Conduit Tables'!$K$4:$K$16,'Conduit Tables'!$E$4:$E$16)),_xlfn.XLOOKUP(TRUE,IF(ISNUMBER(_xlpm.cap),_xlpm.cap>=_xlpm.area,FALSE),_xlpm.sizes,"No size")))} -> 1 | Q35: {=IF($M35="","",_xlfn.LET(_xlpm.area,$O35,_xlpm.cnt,$N35,_xlpm.sizes,'Conduit Tables'!$C$20:$C$26,_xlpm.cap,IF(_xlpm.cnt=1,'Conduit Tables'!$I$20:$I$26,IF(_xlpm.cnt=2,'Conduit Tables'!$K$20:$K$26,'Conduit Tables'!$E$20:$E$26)),_xlfn.XLOOKUP(TRUE,IF(ISNUMBER(_xlpm.cap),_xlpm.cap>=_xlpm.area,FALSE),_xlpm.sizes,"No size")))} -> 1 | R35: {=IF($M35="","",_xlfn.LET(_xlpm.area,$O35,_xlpm.cnt,$N35,_xlpm.sizes,'Conduit Tables'!$C$30:$C$38,_xlpm.cap,IF(_xlpm.cnt=1,'Conduit Tables'!$I$30:$I$38,IF(_xlpm.cnt=2,'Conduit Tables'!$K$30:$K$38,'Conduit Tables'!$E$30:$E$38)),_xlfn.XLOOKUP(TRUE,IF(ISNUMBER(_xlpm.cap),_xlpm.cap>=_xlpm.area,FALSE),_xlpm.sizes,"No size")))} -> 1/2 | S35: 1
A36: TT-3 | E36: NO | F36: 4-20 mA | G36: 2 wire shielded | H36: Dek2C | I36: 1 | J36: RED | K36: R5 | M36: {=IFERROR(INDEX(_xlfn._xlws.SORT(_xlfn.UNIQUE(_xlfn._xlws.FILTER(_xlfn.VSTACK(Table3[[Conduit ]],Table3[Conduit Branch]),_xlfn.VSTACK(Table3[[Conduit ]],Table3[Conduit Branch])<>""))),ROWS($M$27:M36)),"")} -> R1 | N36: {=IF($M36="","",_xlfn.LET(_xlpm.item,$M36,_xlpm.qty,IF(Table3[Cable Qty]="",1,Table3[Cable Qty]),SUMPRODUCT(--(((Table3[[Conduit ]]=_xlpm.item)+(Table3[Conduit Branch]=_xlpm.item))>0),_xlpm.qty)))} -> 9 | O36: {=IF($M36="","",_xlfn.LET(_xlpm.item,$M36,_xlpm.diameters,_xlfn.XLOOKUP(Table3[Cable Designation]&"",Table6[Designation]&"",Table6[Nom Diameter],0),_xlpm.qty,IFERROR(Table3[Cable Qty],1),SUMPRODUCT(((Table3[[Conduit ]]=_xlpm.item)+(Table3[Conduit Branch]=_xlpm.item))*_xlpm.qty*PI()*(_xlpm.diameters/2)^2)))} -> 0.72835391 | P36: {=IF($M36="","",_xlfn.LET(_xlpm.area,$O36,_xlpm.cnt,$N36,_xlpm.sizes,'Conduit Tables'!$C$4:$C$16,_xlpm.cap,IF(_xlpm.cnt=1,'Conduit Tables'!$I$4:$I$16,IF(_xlpm.cnt=2,'Conduit Tables'!$K$4:$K$16,'Conduit Tables'!$E$4:$E$16)),_xlfn.XLOOKUP(TRUE,IF(ISNUMBER(_xlpm.cap),_xlpm.cap>=_xlpm.area,FALSE),_xlpm.sizes,"No size")))} -> 1½ | Q36: {=IF($M36="","",_xlfn.LET(_xlpm.area,$O36,_xlpm.cnt,$N36,_xlpm.sizes,'Conduit Tables'!$C$20:$C$26,_xlpm.cap,IF(_xlpm.cnt=1,'Conduit Tables'!$I$20:$I$26,IF(_xlpm.cnt=2,'Conduit Tables'!$K$20:$K$26,'Conduit Tables'!$E$20:$E$26)),_xlfn.XLOOKUP(TRUE,IF(ISNUMBER(_xlpm.cap),_xlpm.cap>=_xlpm.area,FALSE),_xlpm.sizes,"No size")))} -> 1 1/2 | R36: {=IF($M36="","",_xlfn.LET(_xlpm.area,$O36,_xlpm.cnt,$N36,_xlpm.sizes,'Conduit Tables'!$C$30:$C$38,_xlpm.cap,IF(_xlpm.cnt=1,'Conduit Tables'!$I$30:$I$38,IF(_xlpm.cnt=2,'Conduit Tables'!$K$30:$K$38,'Conduit Tables'!$E$30:$E$38)),_xlfn.XLOOKUP(TRUE,IF(ISNUMBER(_xlpm.cap),_xlpm.cap>=_xlpm.area,FALSE),_xlpm.sizes,"No size")))} -> 1 | S36: 1 1/2
A37: TT-4 | E37: NO | F37: 4-20 mA | G37: 2 wire shielded | H37: Dek2C | I37: 1 | J37: RED | K37: R5 | M37: {=IFERROR(INDEX(_xlfn._xlws.SORT(_xlfn.UNIQUE(_xlfn._xlws.FILTER(_xlfn.VSTACK(Table3[[Conduit ]],Table3[Conduit Branch]),_xlfn.VSTACK(Table3[[Conduit ]],Table3[Conduit Branch])<>""))),ROWS($M$27:M37)),"")} -> R2 | N37: {=IF($M37="","",_xlfn.LET(_xlpm.item,$M37,_xlpm.qty,IF(Table3[Cable Qty]="",1,Table3[Cable Qty]),SUMPRODUCT(--(((Table3[[Conduit ]]=_xlpm.item)+(Table3[Conduit Branch]=_xlpm.item))>0),_xlpm.qty)))} -> 3 | O37: {=IF($M37="","",_xlfn.LET(_xlpm.item,$M37,_xlpm.diameters,_xlfn.XLOOKUP(Table3[Cable Designation]&"",Table6[Designation]&"",Table6[Nom Diameter],0),_xlpm.qty,IFERROR(Table3[Cable Qty],1),SUMPRODUCT(((Table3[[Conduit ]]=_xlpm.item)+(Table3[Conduit Branch]=_xlpm.item))*_xlpm.qty*PI()*(_xlpm.diameters/2)^2)))} -> 0.078868898 | P37: {=IF($M37="","",_xlfn.LET(_xlpm.area,$O37,_xlpm.cnt,$N37,_xlpm.sizes,'Conduit Tables'!$C$4:$C$16,_xlpm.cap,IF(_xlpm.cnt=1,'Conduit Tables'!$I$4:$I$16,IF(_xlpm.cnt=2,'Conduit Tables'!$K$4:$K$16,'Conduit Tables'!$E$4:$E$16)),_xlfn.XLOOKUP(TRUE,IF(ISNUMBER(_xlpm.cap),_xlpm.cap>=_xlpm.area,FALSE),_xlpm.sizes,"No size")))} -> ½ | Q37: {=IF($M37="","",_xlfn.LET(_xlpm.area,$O37,_xlpm.cnt,$N37,_xlpm.sizes,'Conduit Tables'!$C$20:$C$26,_xlpm.cap,IF(_xlpm.cnt=1,'Conduit Tables'!$I$20:$I$26,IF(_xlpm.cnt=2,'Conduit Tables'!$K$20:$K$26,'Conduit Tables'!$E$20:$E$26)),_xlfn.XLOOKUP(TRUE,IF(ISNUMBER(_xlpm.cap),_xlpm.cap>=_xlpm.area,FALSE),_xlpm.sizes,"No size")))} -> 1/2 | R37: {=IF($M37="","",_xlfn.LET(_xlpm.area,$O37,_xlpm.cnt,$N37,_xlpm.sizes,'Conduit Tables'!$C$30:$C$38,_xlpm.cap,IF(_xlpm.cnt=1,'Conduit Tables'!$I$30:$I$38,IF(_xlpm.cnt=2,'Conduit Tables'!$K$30:$K$38,'Conduit Tables'!$E$30:$E$38)),_xlfn.XLOOKUP(TRUE,IF(ISNUMBER(_xlpm.cap),_xlpm.cap>=_xlpm.area,FALSE),_xlpm.sizes,"No size")))} -> 3/8 | S37: 3/4
A38: TT-5 | E38: NO | F38: 4-20 mA | G38: 2 wire shielded | H38: Dek2C | I38: 1 | J38: RED | K38: R3 | M38: {=IFERROR(INDEX(_xlfn._xlws.SORT(_xlfn.UNIQUE(_xlfn._xlws.FILTER(_xlfn.VSTACK(Table3[[Conduit ]],Table3[Conduit Branch]),_xlfn.VSTACK(Table3[[Conduit ]],Table3[Conduit Branch])<>""))),ROWS($M$27:M38)),"")} -> R3 | N38: {=IF($M38="","",_xlfn.LET(_xlpm.item,$M38,_xlpm.qty,IF(Table3[Cable Qty]="",1,Table3[Cable Qty]),SUMPRODUCT(--(((Table3[[Conduit ]]=_xlpm.item)+(Table3[Conduit Branch]=_xlpm.item))>0),_xlpm.qty)))} -> 17 | O38: {=IF($M38="","",_xlfn.LET(_xlpm.item,$M38,_xlpm.diameters,_xlfn.XLOOKUP(Table3[Cable Designation]&"",Table6[Designation]&"",Table6[Nom Diameter],0),_xlpm.qty,IFERROR(Table3[Cable Qty],1),SUMPRODUCT(((Table3[[Conduit ]]=_xlpm.item)+(Table3[Conduit Branch]=_xlpm.item))*_xlpm.qty*PI()*(_xlpm.diameters/2)^2)))} -> 0.40852093 | P38: {=IF($M38="","",_xlfn.LET(_xlpm.area,$O38,_xlpm.cnt,$N38,_xlpm.sizes,'Conduit Tables'!$C$4:$C$16,_xlpm.cap,IF(_xlpm.cnt=1,'Conduit Tables'!$I$4:$I$16,IF(_xlpm.cnt=2,'Conduit Tables'!$K$4:$K$16,'Conduit Tables'!$E$4:$E$16)),_xlfn.XLOOKUP(TRUE,IF(ISNUMBER(_xlpm.cap),_xlpm.cap>=_xlpm.area,FALSE),_xlpm.sizes,"No size")))} -> 1¼ | Q38: {=IF($M38="","",_xlfn.LET(_xlpm.area,$O38,_xlpm.cnt,$N38,_xlpm.sizes,'Conduit Tables'!$C$20:$C$26,_xlpm.cap,IF(_xlpm.cnt=1,'Conduit Tables'!$I$20:$I$26,IF(_xlpm.cnt=2,'Conduit Tables'!$K$20:$K$26,'Conduit Tables'!$E$20:$E$26)),_xlfn.XLOOKUP(TRUE,IF(ISNUMBER(_xlpm.cap),_xlpm.cap>=_xlpm.area,FALSE),_xlpm.sizes,"No size")))} -> 1 1/4 | R38: {=IF($M38="","",_xlfn.LET(_xlpm.area,$O38,_xlpm.cnt,$N38,_xlpm.sizes,'Conduit Tables'!$C$30:$C$38,_xlpm.cap,IF(_xlpm.cnt=1,'Conduit Tables'!$I$30:$I$38,IF(_xlpm.cnt=2,'Conduit Tables'!$K$30:$K$38,'Conduit Tables'!$E$30:$E$38)),_xlfn.XLOOKUP(TRUE,IF(ISNUMBER(_xlpm.cap),_xlpm.cap>=_xlpm.area,FALSE),_xlpm.sizes,"No size")))} -> 3/4 | S38: 1 1/4
A39: TE-8 | E39: NO | F39: 4-20 mA | G39: 3 wire shielded | H39: Dek3C | I39: 1 | J39: RED | K39: R1 | M39: {=IFERROR(INDEX(_xlfn._xlws.SORT(_xlfn.UNIQUE(_xlfn._xlws.FILTER(_xlfn.VSTACK(Table3[[Conduit ]],Table3[Conduit Branch]),_xlfn.VSTACK(Table3[[Conduit ]],Table3[Conduit Branch])<>""))),ROWS($M$27:M39)),"")} -> R4 | N39: {=IF($M39="","",_xlfn.LET(_xlpm.item,$M39,_xlpm.qty,IF(Table3[Cable Qty]="",1,Table3[Cable Qty]),SUMPRODUCT(--(((Table3[[Conduit ]]=_xlpm.item)+(Table3[Conduit Branch]=_xlpm.item))>0),_xlpm.qty)))} -> 6 | O39: {=IF($M39="","",_xlfn.LET(_xlpm.item,$M39,_xlpm.diameters,_xlfn.XLOOKUP(Table3[Cable Designation]&"",Table6[Designation]&"",Table6[Nom Diameter],0),_xlpm.qty,IFERROR(Table3[Cable Qty],1),SUMPRODUCT(((Table3[[Conduit ]]=_xlpm.item)+(Table3[Conduit Branch]=_xlpm.item))*_xlpm.qty*PI()*(_xlpm.diameters/2)^2)))} -> 0.042529311 | P39: {=IF($M39="","",_xlfn.LET(_xlpm.area,$O39,_xlpm.cnt,$N39,_xlpm.sizes,'Conduit Tables'!$C$4:$C$16,_xlpm.cap,IF(_xlpm.cnt=1,'Conduit Tables'!$I$4:$I$16,IF(_xlpm.cnt=2,'Conduit Tables'!$K$4:$K$16,'Conduit Tables'!$E$4:$E$16)),_xlfn.XLOOKUP(TRUE,IF(ISNUMBER(_xlpm.cap),_xlpm.cap>=_xlpm.area,FALSE),_xlpm.sizes,"No size")))} -> ½ | Q39: {=IF($M39="","",_xlfn.LET(_xlpm.area,$O39,_xlpm.cnt,$N39,_xlpm.sizes,'Conduit Tables'!$C$20:$C$26,_xlpm.cap,IF(_xlpm.cnt=1,'Conduit Tables'!$I$20:$I$26,IF(_xlpm.cnt=2,'Conduit Tables'!$K$20:$K$26,'Conduit Tables'!$E$20:$E$26)),_xlfn.XLOOKUP(TRUE,IF(ISNUMBER(_xlpm.cap),_xlpm.cap>=_xlpm.area,FALSE),_xlpm.sizes,"No size")))} -> 3/8 | R39: {=IF($M39="","",_xlfn.LET(_xlpm.area,$O39,_xlpm.cnt,$N39,_xlpm.sizes,'Conduit Tables'!$C$30:$C$38,_xlpm.cap,IF(_xlpm.cnt=1,'Conduit Tables'!$I$30:$I$38,IF(_xlpm.cnt=2,'Conduit Tables'!$K$30:$K$38,'Conduit Tables'!$E$30:$E$38)),_xlfn.XLOOKUP(TRUE,IF(ISNUMBER(_xlpm.cap),_xlpm.cap>=_xlpm.area,FALSE),_xlpm.sizes,"No size")))} -> 3/8 | S39: 3/4
A40: TE-9 | E40: NO | F40: 4-20 mA | G40: 3 wire shielded | H40: Dek3C | I40: 1 | J40: RED | K40: R1 | M40: {=IFERROR(INDEX(_xlfn._xlws.SORT(_xlfn.UNIQUE(_xlfn._xlws.FILTER(_xlfn.VSTACK(Table3[[Conduit ]],Table3[Conduit Branch]),_xlfn.VSTACK(Table3[[Conduit ]],Table3[Conduit Branch])<>""))),ROWS($M$27:M40)),"")} -> R5 | N40: {=IF($M40="","",_xlfn.LET(_xlpm.item,$M40,_xlpm.qty,IF(Table3[Cable Qty]="",1,Table3[Cable Qty]),SUMPRODUCT(--(((Table3[[Conduit ]]=_xlpm.item)+(Table3[Conduit Branch]=_xlpm.item))>0),_xlpm.qty)))} -> 2 | O40: {=IF($M40="","",_xlfn.LET(_xlpm.item,$M40,_xlpm.diameters,_xlfn.XLOOKUP(Table3[Cable Designation]&"",Table6[Designation]&"",Table6[Nom Diameter],0),_xlpm.qty,IFERROR(Table3[Cable Qty],1),SUMPRODUCT(((Table3[[Conduit ]]=_xlpm.item)+(Table3[Conduit Branch]=_xlpm.item))*_xlpm.qty*PI()*(_xlpm.diameters/2)^2)))} -> 0.12938492 | P40: {=IF($M40="","",_xlfn.LET(_xlpm.area,$O40,_xlpm.cnt,$N40,_xlpm.sizes,'Conduit Tables'!$C$4:$C$16,_xlpm.cap,IF(_xlpm.cnt=1,'Conduit Tables'!$I$4:$I$16,IF(_xlpm.cnt=2,'Conduit Tables'!$K$4:$K$16,'Conduit Tables'!$E$4:$E$16)),_xlfn.XLOOKUP(TRUE,IF(ISNUMBER(_xlpm.cap),_xlpm.cap>=_xlpm.area,FALSE),_xlpm.sizes,"No size")))} -> ¾ | Q40: {=IF($M40="","",_xlfn.LET(_xlpm.area,$O40,_xlpm.cnt,$N40,_xlpm.sizes,'Conduit Tables'!$C$20:$C$26,_xlpm.cap,IF(_xlpm.cnt=1,'Conduit Tables'!$I$20:$I$26,IF(_xlpm.cnt=2,'Conduit Tables'!$K$20:$K$26,'Conduit Tables'!$E$20:$E$26)),_xlfn.XLOOKUP(TRUE,IF(ISNUMBER(_xlpm.cap),_xlpm.cap>=_xlpm.area,FALSE),_xlpm.sizes,"No size")))} -> 3/4 | R40: {=IF($M40="","",_xlfn.LET(_xlpm.area,$O40,_xlpm.cnt,$N40,_xlpm.sizes,'Conduit Tables'!$C$30:$C$38,_xlpm.cap,IF(_xlpm.cnt=1,'Conduit Tables'!$I$30:$I$38,IF(_xlpm.cnt=2,'Conduit Tables'!$K$30:$K$38,'Conduit Tables'!$E$30:$E$38)),_xlfn.XLOOKUP(TRUE,IF(ISNUMBER(_xlpm.cap),_xlpm.cap>=_xlpm.area,FALSE),_xlpm.sizes,"No size")))} -> 3/8 | S40: 3/4
...

Sheet Cables Tables
B2: NEC Table 310.15(B)(2)(a) | H2: Number of Conductors | K2: NEC Table 310.16 Cable Ampacity for Raceway / Conduit | S2: NEC Table 250.122 Minimum size equipment grounding conductors EGCs | W2: NEMA Preferred HP ratings for Motors | AD2: NEC Table 310.17
B3: Ambient Temperature | C3: Temperature Rating of Conductor | F3: Ambient Temperature | H3: Number of Conductors | I3: Percent of Values in Table 310.15(B)(16) through Table 310.15(B)(19) as Adjusted for Ambient Temperature if Necessary | K3: Size | L3: Copper Conductors | O3: Aluminum Conductors | S3: OCPD Rating (Amperes) | T3: Copper (AWG or kcmil) | U3: Aluminum or Copper-Clad Aluminum (AWG or kcmil) | W3: HP_Col1 | X3: HP_Col2 | Y3: HP_Col3 | Z3: HP_Col4 | AA3: HP_Col5 | AB3: HP_Col6 | AD3: Size | AE3: Copper Conductors | AH3: Aluminum Conductors
B4: (°C) | C4: 60°C | D4: 75°C | E4: 90°C | F4: (°F) | H4: 4—6 | I4: 80 | K4: AWG/kcmil | L4: 60°C | M4: 75°C | N4: 90°C | O4: 60°C | P4: 75°C | Q4: 90°C | S4: 6000 | T4: 800 kcmil | U4: 1250 kcmil | W4: 1/2 | X4: 10 | Y4: 75 | Z4: 400 | AA4: 1250 | AB4: 4000 | AD4: AWG/kcmil | AE4: 60°C | AF4: 75°C | AG4: 90°C | AH4: 60°C | AI4: 75°C | AJ4: 90°C
B5: 10 or less | C5: 1.29 | D5: 1.2 | E5: 1.15 | F5: 50 or less | H5: 7—9 | I5: 70 | K5: 18 AWG | L5: — | M5: — | N5: 14 | O5: — | P5: — | Q5: — | S5: 5000 | T5: 700 kcmil | U5: 1250 kcmil | W5: 3/4 | X5: 15 | Y5: 100 | Z5: 450 | AA5: 1500 | AB5: 4500 | AD5: 18 AWG | AG5: 18
B6: 11–15 | C6: 1.22 | D6: 1.15 | E6: 1.12 | F6: 51–59 | H6: 10—20 | I6: 50 | K6: 16 AWG | L6: — | M6: — | N6: 18 | O6: — | P6: — | Q6: — | S6: 4000 | T6: 500 kcmil | U6: 750 kcmil | W6: 1 | X6: 20 | Y6: 125 | Z6: 500 | AA6: 1750 | AB6: 5000 | AD6: 16 AWG | AG6: 24
B7: 16–20 | C7: 1.15 | D7: 1.11 | E7: 1.08 | F7: 60–68 | H7: 21—30 | I7: 45 | K7: 14 AWG | L7: 20 | M7: 25 | N7: 30 | O7: — | P7: — | Q7: — | S7: 3000 | T7: 400 kcmil | U7: 600 kcmil | W7: 1-1/2 | X7: 25 | Y7: 150 | Z7: 600 | AA7: 2000 | AB7: - | AD7: 14 AWG | AE7: 25 | AF7: 30 | AG7: 35
B8: 21–25 | C8: 1.08 | D8: 1.05 | E8: 1.04 | F8: 69–77 | H8: 31—40 | I8: 40 | K8: 12 AWG | L8: 25 | M8: 30 | N8: 35 | O8: 20 | P8: 25 | Q8: 30 | S8: 2500 | T8: 350 kcmil | U8: 600 kcmil | W8: 2 | X8: 30 | Y8: 200 | Z8: 700 | AA8: 2250 | AB8: - | AD8: 12 AWG | AE8: 30 | AF8: 35 | AG8: 40 | AH8: 25 | AI8: 30 | AJ8: 35
B9: 26–30 | C9: 1 | D9: 1 | E9: 1 | F9: 78–86 | H9: 41 and above | I9: 35 | K9: 10 AWG | L9: 30 | M9: 35 | N9: 40 | O9: 25 | P9: 30 | Q9: 35 | S9: 2000 | T9: 250 kcmil | U9: 400 kcmil | W9: 3 | X9: 40 | Y9: 250 | Z9: 800 | AA9: 2500 | AB9: - | AD9: 10 AWG | AE9: 40 | AF9: 50 | AG9: 55 | AH9: 35 | AI9: 40 | AJ9: 45
B10: 31–35 | C10: 0.91 | D10: 0.94 | E10: 0.96 | F10: 87–95 | K10: 8 AWG | L10: 40 | M10: 50 | N10: 55 | O10: 35 | P10: 40 | Q10: 45 | S10: 1600 | T10: 4/0 AWG | U10: 350 kcmil | W10: 5 | X10: 50 | Y10: 300 | Z10: 900 | AA10: 3000 | AB10: - | AD10: 8 AWG | AE10: 60 | AF10: 70 | AG10: 80 | AH10: 45 | AI10: 55 | AJ10: 60
B11: 36–40 | C11: 0.82 | D11: 0.88 | E11: 0.91 | F11: 96–104 | K11: 6 AWG | L11: 55 | M11: 65 | N11: 75 | O11: 40 | P11: 50 | Q11: 60 | S11: 1200 | T11: 3/0 AWG | U11: 250 kcmil | W11: 7-1/2 | X11: 60 | Y11: 350 | Z11: 1000 | AA11: 3500 | AB11: - | AD11: 6 AWG | AE11: 80 | AF11: 95 | AG11: 105 | AH11: 60 | AI11: 75 | AJ11: 85
B12: 41–45 | C12: 0.71 | D12: 0.82 | E12: 0.87 | F12: 105–113 | K12: 4 AWG | L12: 70 | M12: 85 | N12: 95 | O12: 55 | P12: 65 | Q12: 75 | S12: 1000 | T12: 2/0 AWG | U12: 4/0 AWG | AD12: 4 AWG | AE12: 105 | AF12: 125 | AG12: 140 | AH12: 80 | AI12: 100 | AJ12: 115
B13: 46–50 | C13: 0.58 | D13: 0.75 | E13: 0.82 | F13: 114–122 | K13: 3 AWG | L13: 85 | M13: 100 | N13: 110 | O13: 65 | P13: 75 | Q13: 85 | S13: 800 | T13: 1/0 AWG | U13: 3/0 AWG | AD13: 3 AWG | AE13: 120 | AF13: 145 | AG13: 165 | AH13: 95 | AI13: 115 | AJ13: 130
B14: 51–55 | C14: 0.41 | D14: 0.67 | E14: 0.76 | F14: 123–131 | H14: Rating | I14: Common Insulation Types | K14: 2 AWG | L14: 95 | M14: 115 | N14: 130 | O14: 75 | P14: 90 | Q14: 100 | S14: 600 | T14: 1 AWG | U14: 2/0 AWG | W14: NEMA Preferred RPM ratings for Motors | AD14: 2 AWG | AE14: 140 | AF14: 170 | AG14: 190 | AH14: 110 | AI14: 135 | AJ14: 150
B15: 56–60 | C15: — | D15: 0.58 | E15: 0.71 | F15: 132–140 | H15: 60°C | I15: TW, UF | K15: 1 AWG | L15: 110 | M15: 130 | N15: 150 | O15: 85 | P15: 100 | Q15: 115 | S15: 500 | T15: 2 AWG | U15: 1/0 AWG | W15: Speed_Col1 | X15: Speed_Col2 | Y15: Speed_Col3 | Z15: Speed_Col4 | AD15: 1 AWG | AE15: 165 | AF15: 195 | AG15: 220 | AH15: 130 | AI15: 155 | AJ15: 175
B16: 61–65 | C16: — | D16: 0.47 | E16: 0.65 | F16: 141–149 | H16: 75°C | I16: THW, THWN, RHW, XHHW (wet) | K16: 1/0 AWG | L16: 125 | M16: 150 | N16: 170 | O16: 100 | P16: 120 | Q16: 135 | S16: 400 | T16: 3 AWG | U16: 1 AWG | W16: 300 | X16: 650 | Y16: 1750 | Z16: 5000 | AD16: 1/0 AWG | AE16: 195 | AF16: 230 | AG16: 260 | AH16: 150 | AI16: 180 | AJ16: 205
B17: 66–70 | C17: — | D17: 0.33 | E17: 0.58 | F17: 150–158 | H17: 90°C | I17: THHN, THWN-2, XHHW-2, USE-2 | K17: 2/0 AWG | L17: 145 | M17: 175 | N17: 195 | O17: 115 | P17: 135 | Q17: 150 | S17: 300 | T17: 4 AWG | U17: 2 AWG | W17: 400 | X17: 850 | Y17: 2500 | Z17: 7000 | AD17: 2/0 AWG | AE17: 225 | AF17: 265 | AG17: 300 | AH17: 175 | AI17: 210 | AJ17: 235
B18: 71–75 | C18: — | D18: — | E18: 0.5 | F18: 159–167 | K18: 3/0 AWG | L18: 165 | M18: 200 | N18: 225 | O18: 130 | P18: 155 | Q18: 175 | S18: 200 | T18: 6 AWG | U18: 4 AWG | W18: 500 | X18: 1150 | Y18: 3500 | Z18: 10000 | AD18: 3/0 AWG | AE18: 260 | AF18: 310 | AG18: 350 | AH18: 200 | AI18: 240 | AJ18: 270
B19: 76–80 | C19: — | D19: — | E19: 0.41 | F19: 168–176 | K19: 4/0 AWG | L19: 195 | M19: 230 | N19: 260 | O19: 150 | P19: 180 | Q19: 205 | S19: 100 | T19: 8 AWG | U19: 6 AWG | AD19: 4/0 AWG | AE19: 300 | AF19: 360 | AG19: 405 | AH19: 235 | AI19: 280 | AJ19: 315
B20: 81–85 | C20: — | D20: — | E20: 0.29 | F20: 177–185 | K20: 250 kcmil | L20: 215 | M20: 255 | N20: 290 | O20: 170 | P20: 205 | Q20: 230 | S20: 60 | T20: 10 AWG | U20: 8 AWG | AD20: 250 kcmil | AE20: 340 | AF20: 405 | AG20: 455 | AH20: 265 | AI20: 315 | AJ20: 355
K21: 300 kcmil | L21: 240 | M21: 285 | N21: 320 | O21: 190 | P21: 230 | Q21: 255 | S21: 20 | T21: 12 AWG | U21: 10 AWG | AD21: 300 kcmil | AE21: 375 | AF21: 445 | AG21: 500 | AH21: 290 | AI21: 350 | AJ21: 395
K22: 350 kcmil | L22: 260 | M22: 310 | N22: 350 | O22: 210 | P22: 250 | Q22: 280 | S22: 15 | T22: 14 AWG | U22: 12 AWG | AD22: 350 kcmil | AE22: 420 | AF22: 505 | AG22: 570 | AH22: 330 | AI22: 395 | AJ22: 445
K23: 400 kcmil | L23: 280 | M23: 335 | N23: 380 | O23: 225 | P23: 270 | Q23: 305 | AD23: 400 kcmil | AE23: 455 | AF23: 545 | AG23: 615 | AH23: 355 | AI23: 425 | AJ23: 480
K24: 500 kcmil | L24: 320 | M24: 380 | N24: 430 | O24: 260 | P24: 310 | Q24: 350 | AD24: 500 kcmil | AE24: 515 | AF24: 620 | AG24: 700 | AH24: 405 | AI24: 485 | AJ24: 545
K25: 600 kcmil | L25: 355 | M25: 420 | N25: 475 | O25: 285 | P25: 340 | Q25: 385 | AD25: 600 kcmil | AE25: 575 | AF25: 690 | AG25: 780 | AH25: 455 | AI25: 545 | AJ25: 615
K26: 700 kcmil | L26: 385 | M26: 460 | N26: 520 | O26: 310 | P26: 375 | Q26: 425 | AD26: 700 kcmil | AE26: 630 | AF26: 755 | AG26: 850 | AH26: 500 | AI26: 595 | AJ26: 670
K27: 750 kcmil | L27: 400 | M27: 475 | N27: 535 | O27: 320 | P27: 385 | Q27: 435 | AD27: 750 kcmil | AE27: 655 | AF27: 785 | AG27: 885 | AH27: 515 | AI27: 620 | AJ27: 700
K28: 800 kcmil | L28: 410 | M28: 490 | N28: 555 | O28: 330 | P28: 395 | Q28: 445 | AD28: 800 kcmil | AE28: 680 | AF28: 815 | AG28: 920 | AH28: 535 | AI28: 645 | AJ28: 725
K29: 900 kcmil | L29: 435 | M29: 520 | N29: 585 | O29: 355 | P29: 425 | Q29: 480 | AD29: 900 kcmil | AE29: 730 | AF29: 870 | AG29: 980 | AH29: 580 | AI29: 700 | AJ29: 790
K30: 1000 kcmil | L30: 455 | M30: 545 | N30: 615 | O30: 375 | P30: 445 | Q30: 500 | AD30: 1000 kcmil | AE30: 780 | AF30: 935 | AG30: 1055 | AH30: 625 | AI30: 750 | AJ30: 845
K31: 1250 kcmil | L31: 495 | M31: 590 | N31: 665 | O31: 405 | P31: 485 | Q31: 545 | AD31: 1250 kcmil | AE31: 890 | AF31: 1065 | AG31: 1200 | AH31: 710 | AI31: 855 | AJ31: 965
K32: 1500 kcmil | L32: 525 | M32: 625 | N32: 705 | O32: 435 | P32: 520 | Q32: 585 | AD32: 1500 kcmil | AE32: 980 | AF32: 1175 | AG32: 1325 | AH32: 795 | AI32: 950 | AJ32: 1070
K33: 1750 kcmil | L33: 545 | M33: 650 | N33: 735 | O33: 455 | P33: 545 | Q33: 615 | AD33: 1750 kcmil | AE33: 1070 | AF33: 1280 | AG33: 1445 | AH33: 875 | AI33: 1050 | AJ33: 1185
K34: 2000 kcmil | L34: 555 | M34: 665 | N34: 750 | O34: 470 | P34: 560 | Q34: 630 | AD34: 2000 kcmil | AE34: 1155 | AF34: 1385 | AG34: 1560 | AH34: 960 | AI34: 1150 | AJ34: 1295

Sheet Conduit Fittings
A1: Conduit BOM | F1: BILL OF MATERIAL | N1: Conduit Planning
A2: Size | B2: Part | C2: BOM Qty | D2: EPICOR P/N | E2: EPICOR DESCRIPTION | F2: Number | G2: ASM | H2: Mtl Seq | I2: Part | J2: Qty / Parent | K2: UOM | L2: Desc | N2: Size | O2: Tag | P2: Transcribed Contents
A3: #18 AWG | B3: Cable | C3: 30 | D3: 241000309 | E3: MOTOR RTD CABLE, AWG 18, 600 VOLT, LAPP-25 COND | F3: 12 | G3: 68 | H3: 120 | I3: 50110023 | J3: 1 | K3: EA | L3: 1" MEYERS HUB | N3: 1 | O3: GN | P3: MH, LB, TB, 90, X, T
A4: 1 1/4" -> 3/4" | B4: RD | C4: 2 | D4: 241000201 | E4: 1-1/4" X 3/4" RE BUSHING | F4: 29 | G4: 68 | H4: 290 | I4: 50110125 | J4: 4 | K4: EA | L4: 1" X 3/4" RE BUSHING | N4: 1-1/4 | O4: R3 | P4: RD, T, down T,T,T,T,T, 90, X
A5: 1" | B5: 90° | C5: 1 | D5: 241000125 | E5: 1" 90 DEG. PULL ELB FEM / FEM NON HAZ LOC | F5: 11 | G5: 68 | H5: 110 | I5: 50110860 | J5: 1 | K5: EA | L5: 3/4" MEYERS HUB | N5: 1-1/4 | O5: Y4 | P5: RD, T, d, T, X, X, X, X, X
A6: 1" | B6: LB | C6: 1 | D6: 241000118 | E6: 1" MALL LB COND BODY | F6: 7 | G6: 68 | H6: 70 | I6: 50111204 | J6: 4 | K6: EA | L6: COND BODY, MALL, LB, 1/2" | N6: 2 | O6: Red | P6: MH, LB, TB, 90, X, 90, X, X, T, T, 90
A7: 1" | B7: MH | C7: 1 | D7: 50110023 | E7: 1" MEYERS HUB | F7: 26 | G7: 68 | H7: 260 | I7: 50111400 | J7: 6 | K7: EA | L7: COND BODY, MALL X, 1-1/4" | N7: 2 | O7: YW | P7: MH, LB, X, LR, T,T,T,X,X
A8: 1" | B8: T | C8: 1 | D8: 241000185 | E8: COND BODY, MALL, T, 1" | F8: 15 | G8: 68 | H8: 150 | I8: 50111404 | J8: 15 | K8: EA | L8: COND BODY, MALL T, 3/4" | N8: 3/4 | O8: B1
A9: 1" | B9: TB | C9: 1 | D9: 241000122 | E9: 1" MALL TB CONDUIT BODY | F9: 14 | G9: 68 | H9: 140 | I9: 50112048 | J9: 2 | K9: EA | L9: SEAL OFF, MALL, EYS, 3/4" | N9: 3/4 | O9: B2
A10: 1" | B10: X | C10: 1 | D10: 241000199 | E10: 1" MALL X CONDUIT BODY | F10: 24 | G10: 68 | H10: 240 | I10: 50112205 | J10: 8 | K10: EA | L10: COND BODY, MALL, X, 3/4", CLIP | N10: 3/4 | O10: BL | P10: MH, LB, TB, ELB, X, X
A11: 1" -> 3/4" | B11: RD | C11: 4 | D11: 50110125 | E11: 1" X 3/4" RE BUSHING | F11: 20 | G11: 68 | H11: 200 | I11: 50112229 | J11: 2 | K11: EA | L11: 3/4" MALL TB COND BODY | N11: 3/4 | O11: G1 | P11: RD, 90°, C
A12: 1/2" | B12: LB | C12: 4 | D12: 50111204 | E12: COND BODY, MALL, LB, 1/2" | F12: 5 | G12: 68 | H12: 50 | I12: 50112244 | J12: 1 | K12: EA | L12: 3/4" MALE / FEM 90 DEG SHORT ELB HAZ LOC | N12: 3/4 | O12: G2 | P12: RD, X, T, X, LB, TB, UNION90, SEAL, UNION90, SEAL, T, 90, T W DRAIN, C
A13: 1-1/4" | B13: 90° | C13: 1 | D13: 241000126 | E13: COND BODY, MALL, LB, 1-1/4" | F13: 18 | G13: 68 | H13: 180 | I13: 241000071 | J13: 2 | K13: EA | L13: COND BODY, MALL, T, 2" | N13: 3/4 | O13: R1 | P13: RD, T
A14: 1-1/4" | B14: T | C14: 9 | D14: 241000179 | E14: COND BODY, MALL, T, 1-1/4" | F14: 22 | G14: 68 | H14: 220 | I14: 241000072 | J14: 1 | K14: EA | L14: 2" MALL TB COND BODY | N14: 3/4 | O14: R2 | P14: RD, T LB
A15: 1-1/4" | B15: X | C15: 6 | D15: 50111400 | E15: COND BODY, MALL X, 1-1/4" | F15: 13 | G15: 68 | H15: 130 | I15: 241000082 | J15: 2 | K15: EA | L15: MEYERS HUB, 2" | N15: 3/4 | O15: R4 | P15: RD, T
A16: 2" | B16: LB | C16: 5 | D16: 241000198 | E16: COND BODY, MALL, LB, 2" | F16: 1 | G16: 68 | H16: 10 | I16: 241000094 | J16: 4 | K16: EA | L16: PULL ELBOW, NON HAZ LOC, 90 DEG. MALE / FEM, 3/4" | N16: 3/4 | O16: R5 | P16: RD, T, down TT4 T, up TT3 T
A17: 2" | B17: LR | C17: 1 | D17: 241000101 | E17: COND BODY, MALL, LR, 2" | F17: 27 | G17: 68 | H17: 270 | I17: 241000100 | J17: 6 | K17: EA | L17: 2" MALL X COND BODY | N17: 3/4 | O17: Y1 | P17: RD
A18: 2" | B18: MH | C18: 2 | D18: 241000082 | E18: MEYERS HUB, 2" | F18: 10 | G18: 68 | H18: 100 | I18: 241000101 | J18: 1 | K18: EA | L18: COND BODY, MALL, LR, 2" | N18: 3/4 | O18: Y2 | P18: RD, T, X
A19: 2" | B19: T | C19: 2 | D19: 241000071 | E19: COND BODY, MALL, T, 2" | F19: 23 | G19: 68 | H19: 230 | I19: 241000109 | J19: 2 | K19: EA | L19: UNION, MALL, HAZ LOC, 90, UNL, 3/4" | N19: 3/4 | O19: Y3 | P19: RD, T, T, T, 90, LB
A20: 2" | B20: TB | C20: 1 | D20: 241000072 | E20: 2" MALL TB COND BODY | F20: 4 | G20: 68 | H20: 40 | I20: 241000116 | J20: 2 | K20: EA | L20: 3/4" MALL C COND BODY, CLIP | N20: 3/4 | O20: Y5 | P20: RD, X, X, RD -> 1/2" LB, 1/2" LB, 1/2" LB, 1/2" LB
A21: 2" | B21: X | C21: 6 | D21: 241000100 | E21: 2" MALL X COND BODY | F21: 19 | G21: 68 | H21: 190 | I21: 241000117 | J21: 16 | K21: EA | L21: DRAIN BREATHER, 3/4" | N21: 3/4 | O21: Y6 | P21: RD, T, 90, X
A22: 2" -> 1 1/4" | B22: RD | C22: 2 | D22: 241000200 | E22: RE BUSH, 2" X 1-1/4" | F22: 8 | G22: 68 | H22: 80 | I22: 241000118 | J22: 1 | K22: EA | L22: 1" MALL LB COND BODY
A23: 2" -> 3/4" | B23: RD | C23: 15 | D23: 241000194 | E23: RE BUSH, 2" X 3/4" | F23: 21 | G23: 68 | H23: 210 | I23: 241000122 | J23: 1 | K23: EA | L23: 1" MALL TB CONDUIT BODY
A24: 3/4" | B24: 90° | C24: 4 | D24: 241000094 | E24: PULL ELBOW, NON HAZ LOC, 90 DEG. MALE / FEM, 3/4" | F24: 2 | G24: 68 | H24: 20 | I24: 241000125 | J24: 1 | K24: EA | L24: 1" 90 DEG. PULL ELB FEM / FEM NON HAZ LOC
A25: 3/4" | B25: C | C25: 2 | D25: 241000116 | E25: 3/4" MALL C COND BODY, CLIP | F25: 3 | G25: 68 | H25: 30 | I25: 241000126 | J25: 1 | K25: EA | L25: COND BODY, MALL, LB, 1-1/4"
A26: 3/4" | B26: Drain | C26: 16 | D26: 241000117 | E26: DRAIN BREATHER, 3/4" | F26: 17 | G26: 68 | H26: 170 | I26: 241000179 | J26: 9 | K26: EA | L26: COND BODY, MALL, T, 1-1/4"
A27: 3/4" | B27: ELB | C27: 1 | D27: 50112244 | E27: 3/4" MALE / FEM 90 DEG SHORT ELB HAZ LOC | F27: 16 | G27: 68 | H27: 160 | I27: 241000185 | J27: 1 | K27: EA | L27: COND BODY, MALL, T, 1"
A28: 3/4" | B28: LB | C28: 4 | D28: 241000187 | E28: COND BODY, MALL, LB, 3/4" | F28: 6 | G28: 68 | H28: 60 | I28: 241000187 | J28: 4 | K28: EA | L28: COND BODY, MALL, LB, 3/4"
A29: 3/4" | B29: MH | C29: 1 | D29: 50110860 | E29: 3/4" MEYERS HUB | F29: 28 | G29: 68 | H29: 280 | I29: 241000194 | J29: 15 | K29: EA | L29: RE BUSH, 2" X 3/4"
A30: 3/4" | B30: Seal | C30: 2 | D30: 50112048 | E30: SEAL OFF, MALL, EYS, 3/4" | F30: 9 | G30: 68 | H30: 90 | I30: 241000198 | J30: 5 | K30: EA | L30: COND BODY, MALL, LB, 2"
A31: 3/4" | B31: T | C31: 15 | D31: 50111404 | E31: COND BODY, MALL T, 3/4" | F31: 25 | G31: 68 | H31: 250 | I31: 241000199 | J31: 1 | K31: EA | L31: 1" MALL X CONDUIT BODY
A32: 3/4" | B32: TB | C32: 2 | D32: 50112229 | E32: 3/4" MALL TB COND BODY | F32: 30 | G32: 68 | H32: 300 | I32: 241000200 | J32: 2 | K32: EA | L32: RE BUSH, 2" X 1-1/4"
A33: 3/4" | B33: Union 90 | C33: 2 | D33: 241000109 | E33: UNION, MALL, HAZ LOC, 90, UNL, 3/4" | F33: 31 | G33: 68 | H33: 310 | I33: 241000201 | J33: 2 | K33: EA | L33: 1-1/4" X 3/4" RE BUSHING
A34: 3/4" | B34: X | C34: 8 | D34: 50112205 | E34: COND BODY, MALL, X, 3/4", CLIP | F34: 32 | G34: 68 | H34: 320 | I34: 241000309 | J34: 30 | K34: FT | L34: MOTOR RTD CABLE, AWG 18, 600 VOLT, LAPP-25 COND
A36: Conduit Planning
A37: Size | B37: Tag | C37: Transcribed Contents
A38: 1 | B38: GN | C38: MH, LB, TB, 90, X, T
A39: 1-1/4 | B39: R3 | C39: RD, T, down T,T,T,T,T, 90, X
A40: 1-1/4 | B40: Y4 | C40: RD, T, d, T, X, X, X, X, X
A41: 2 | B41: Red | C41: MH, LB, TB, 90, X, 90, X, X, T, T, 90
...

Sheet Conduit Tables
B2: Article 344 - Rigid Metal Conduit | R2: Chapter 9 Table 2 Radius of Conduit and Tubing Bends
B3: Metric Designator | C3: Trade Size | D3: Over 2 Wires 40% mm² | E3: Over 2 Wires 40% in.² | F3: 1 Wire 60% mm² | G3: 1 Wire 60% in.² | H3: 1 Wire 53% mm² | I3: 1 Wire 53% in.² | J3: 2 Wires 31% mm² | K3: 2 Wires 31% in.² | L3: Nominal Internal Diameter mm | M3: Nominal Internal Diameter in. | N3: Total Area 100% mm² | O3: Total Area 100% in.² | R3: Metric Designator | S3: Trade Size | T3: One Shot/Full Shoe (mm) | U3: One Shot/Full Shoe (in) | V3: Other Bends (mm) | W3: Other Bends (in)
B4: 12 | C4: ⅜ | D4: — | E4: — | F4: — | G4: — | H4: — | I4: — | J4: — | K4: — | L4: 16.1 | M4: 0.632 | N4: 204 | O4: 0.314 | R4: 16 | S4: 0.5 | T4: 101.6 | U4: 4 | V4: 101.6 | W4: 4
B5: 16 | C5: ½ | D5: 81 | E5: 0.125 | F5: 122 | G5: 0.188 | H5: 107 | I5: 0.166 | J5: 63 | K5: 0.097 | L5: 21 | M5: 0.832 | N5: 204 | O5: 0.314 | R5: 21 | S5: 0.75 | T5: 114.3 | U5: 4.5 | V5: 127 | W5: 5
B6: 21 | C6: ¾ | D6: 141 | E6: 0.22 | F6: 212 | G6: 0.328 | H6: 185 | I6: 0.291 | J6: 109 | K6: 0.17 | L6: 21.2 | M6: 0.836 | N6: 353 | O6: 0.549 | R6: 27 | S6: 1 | T6: 146.05 | U6: 5.75 | V6: 152.4 | W6: 6
B7: 27 | C7: 1 | D7: 229 | E7: 0.355 | F7: 344 | G7: 0.532 | H7: 302 | I7: 0.47 | J7: 177 | K7: 0.275 | L7: 27 | M7: 1.063 | N7: 573 | O7: 0.887 | R7: 35 | S7: 1.25 | T7: 184.15 | U7: 7.25 | V7: 203.2 | W7: 8
B8: 35 | C8: 1¼ | D8: 394 | E8: 0.61 | F8: 533 | G8: 0.826 | H8: 468 | I8: 0.709 | J8: 305 | K8: 0.473 | L8: 35.4 | M8: 1.394 | N8: 981 | O8: 1.526 | R8: 41 | S8: 1.5 | T8: 209.55 | U8: 8.25 | V8: 254 | W8: 10
B9: 41 | C9: 1½ | D9: 533 | E9: 0.825 | F9: 800 | G9: 1.243 | H9: 702 | I9: 1.089 | J9: 395 | K9: 0.613 | L9: 41.6 | M9: 1.638 | N9: 1333 | O9: 2.071 | R9: 53 | S9: 2 | T9: 241.3 | U9: 9.5 | V9: 304.8 | W9: 12
B10: 53 | C10: 2 | D10: 879 | E10: 1.363 | F10: 1318 | G10: 2.045 | H10: 1157 | I10: 1.806 | J10: 681 | K10: 1.056 | L10: 52.9 | M10: 2.083 | N10: 2198 | O10: 3.409 | R10: 63 | S10: 2.5 | T10: 266.7 | U10: 10.5 | V10: 381 | W10: 15
B11: 63 | C11: 2½ | D11: 1255 | E11: 1.946 | F11: 1882 | G11: 2.918 | H11: 1654 | I11: 2.563 | J11: 974 | K11: 1.51 | L11: 63.1 | M11: 2.484 | N11: 3129 | O11: 4.866 | R11: 78 | S11: 3 | T11: 330.2 | U11: 13 | V11: 457.2 | W11: 18
B12: 78 | C12: 3 | D12: 1936 | E12: 3.004 | F12: 2904 | G12: 4.509 | H12: 2553 | I12: 3.974 | J12: 1503 | K12: 2.34 | L12: 78.5 | M12: 3.09 | N12: 4844 | O12: 7.499 | R12: 91 | S12: 3.5 | T12: 381 | U12: 15 | V12: 533.4 | W12: 21
B13: 91 | C13: 3½ | D13: 2584 | E13: 4.004 | F13: 3877 | G13: 6.006 | H13: 3414 | I13: 5.294 | J13: 2000 | K13: 3.099 | L13: 90.7 | M13: 3.57 | N13: 6460 | O13: 10.01 | R13: 103 | S13: 4 | T13: 406.4 | U13: 16 | V13: 609.6 | W13: 24
B14: 103 | C14: 4 | D14: 3326 | E14: 5.153 | F14: 4990 | G14: 7.728 | H14: 4396 | I14: 6.828 | J14: 2578 | K14: 3.994 | L14: 102.9 | M14: 4.053 | N14: 8316 | O14: 12.882 | R14: 129 | S14: 5 | T14: 609.6 | U14: 24 | V14: 762 | W14: 30
B15: 129 | C15: 5 | D15: 5220 | E15: 8.085 | F15: 7830 | G15: 12.127 | H15: 6896 | I15: 10.667 | J15: 4045 | K15: 6.265 | L15: 129.8 | M15: 5.073 | N15: 13050 | O15: 20.212 | R15: 155 | S15: 6 | T15: 762 | U15: 30 | V15: 914.4 | W15: 36
B16: 155 | C16: 6 | D16: 7528 | E16: 11.663 | F16: 11292 | G16: 17.495 | H16: 9975 | I16: 15.454 | J16: 5843 | K16: 9.03 | L16: 154.8 | M16: 6.09 | N16: 18821 | O16: 29.158
B18: Article 356 - Liquidtight Flexible Nonmetallic Conduit
B19: Metric Designator | C19: Trade Size | D19: Over 2 Wires 40% (mm²) | E19: Over 2 Wires 40% (in²) | F19: 60% (mm²) | G19: 60% (in²) | H19: 1 Wire 53% (mm²) | I19: 1 Wire 53% (in²) | J19: 2 Wires 31% (mm²) | K19: 2 Wires 31% (in²) | L19: Nominal ID (mm) | M19: Nominal ID (in) | N19: Total Area 100% (mm²) | O19: Total Area 100% (in²)
B20: 12 | C20: 3/8 | D20: 50 | E20: 0.077 | F20: 75 | G20: 0.115 | H20: 66 | I20: 0.102 | J20: 39 | K20: 0.06 | L20: 12.6 | M20: 0.495 | N20: 125 | O20: 0.192
B21: 16 | C21: 1/2 | D21: 80 | E21: 0.125 | F21: 121 | G21: 0.187 | H21: 107 | I21: 0.165 | J21: 62 | K21: 0.097 | L21: 16 | M21: 0.63 | N21: 201 | O21: 0.312
B22: 21 | C22: 3/4 | D22: 139 | E22: 0.214 | F22: 208 | G22: 0.321 | H22: 184 | I22: 0.283 | J22: 107 | K22: 0.166 | L22: 21 | M22: 0.825 | N22: 346 | O22: 0.535
B23: 27 | C23: 1 | D23: 221 | E23: 0.343 | F23: 331 | G23: 0.513 | H23: 292 | I23: 0.453 | J23: 171 | K23: 0.265 | L23: 26.5 | M23: 1.043 | N23: 552 | O23: 0.854
B24: 35 | C24: 1 1/4 | D24: 387 | E24: 0.601 | F24: 581 | G24: 0.901 | H24: 513 | I24: 0.796 | J24: 300 | K24: 0.466 | L24: 35.1 | M24: 1.383 | N24: 968 | O24: 1.502
B25: 41 | C25: 1 1/2 | D25: 520 | E25: 0.807 | F25: 781 | G25: 1.211 | H25: 690 | I25: 1.07 | J25: 403 | K25: 0.626 | L25: 40.7 | M25: 1.603 | N25: 1301 | O25: 2.018
B26: 53 | C26: 2 | D26: 863 | E26: 1.337 | F26: 1294 | G26: 2.006 | H26: 1143 | I26: 1.772 | J26: 669 | K26: 1.036 | L26: 52.4 | M26: 2.063 | N26: 2157 | O26: 3.343
B28: Article 348 - Flexible Metal Conduit
B29: Metric Designator | C29: Trade Size | D29: Over 2 Wires 40% (mm²) | E29: Over 2 Wires 40% (in²) | F29: 60% (mm²) | G29: 60% (in²) | H29: 1 Wire 53% (mm²) | I29: 1 Wire 53% (in²) | J29: 2 Wires 31% (mm²) | K29: 2 Wires 31% (in²) | L29: Nominal ID (mm) | M29: Nominal ID (in) | N29: Total Area 100% (mm²) | O29: Total Area 100% (in²)
B30: 12 | C30: 3/8 | D30: 127 | E30: 0.197 | F30: 206 | G30: 0.32 | H30: 182 | I30: 0.283 | J30: 106 | K30: 0.165 | L30: 10.9 | M30: 0.424 | N30: 345 | O30: 0.535
B31: 16 | C31: 1/2 | D31: 211 | E31: 0.327 | F31: 316 | G31: 0.49 | H31: 279 | I31: 0.433 | J31: 162 | K31: 0.253 | L31: 15.9 | M31: 0.622 | N31: 527 | O31: 0.817
B32: 21 | C32: 3/4 | D32: 330 | E32: 0.511 | F32: 495 | G32: 0.766 | H32: 437 | I32: 0.677 | J32: 253 | K32: 0.396 | L32: 22.4 | M32: 0.882 | N32: 824 | O32: 1.277
B33: 27 | C33: 1 | D33: 480 | E33: 0.743 | F33: 720 | G33: 1.111 | H33: 636 | I33: 0.985 | J33: 372 | K33: 0.576 | L33: 29.1 | M33: 1.138 | N33: 1201 | O33: 1.863
B34: 35 | C34: 1 1/4 | D34: 843 | E34: 1.307 | F34: 1264 | G34: 1.961 | H34: 1117 | I34: 1.732 | J34: 653 | K34: 1.013 | L34: 39.1 | M34: 1.54 | N34: 2107 | O34: 3.269
B35: 41 | C35: 1 1/2 | D35: 1267 | E35: 1.963 | F35: 1900 | G35: 2.945 | H35: 1678 | I35: 2.602 | J35: 980 | K35: 1.522 | L35: 63.5 | M35: 2.5 | N35: 3167 | O35: 4.909
B36: 53 | C36: 2 | D36: 1854 | E36: 2.877 | F36: 2736 | G36: 4.241 | H36: 2417 | I36: 3.746 | J36: 1414 | K36: 2.191 | L36: 76.9 | M36: 3.001 | N36: 4560 | O36: 7.068
B37: 63 | C37: 2 1/2 | D37: 2483 | E37: 3.848 | F37: 3724 | G37: 5.773 | H37: 3390 | I37: 5.009 | J37: 1921 | K37: 2.983 | L37: 88.9 | M37: 3.5 | N37: 6207 | O37: 9.621
B38: 78 | C38: 3 | D38: 3243 | E38: 5.027 | F38: 4861 | G38: 7.54 | H38: 4297 | I38: 6.66 | J38: 2515 | K38: 3.896 | L38: 101.6 | M38: 4 | N38: 8107 | O38: 12.566
H40: Lookup Calculation
B41: Type | C41: Size (AWG/kcmil) | D41: Area mm^2 | E41: Area in^2 | F41: Diameter mm | G41: Diameter in | H41: 0
B42: KF-1, KFF-1 | C42: 10 AWG | D42: 8.194 | E42: 0.0127 | F42: 3.226 | G42: 0.127
B43: KF-1, KFF-1 | C43: 12 AWG | D43: 5.355 | E43: 0.0083 | F43: 2.616 | G43: 0.103
B44: KF-1, KFF-1 | C44: 14 AWG | D44: 3.548 | E44: 0.0055 | F44: 2.134 | G44: 0.084
...

Sheet EPICOR ELECTRIC PARTS
A1: SEARCH WORD | B1: EPICOR P/N | C1: NEW P/N | D1: EPICOR DESCRIPTION | E1: NEW DESCRIPTION | F1: SIZE | G1: BIN LOCATION EC RACK | H1: QTY | I1: QTY BIN LOCATION 2 | J1: NOTES
A2: FASTENER | C2: 241000208 | E2: HEX HEAD SCREW M8 X 1.25 X 20 MM (PACKS OF 10 EACH) | F2: M8 | G2: EC6-3 | J2: McMaster P/N 93635A318
A3: TERMFITT | C3: 241000135 | E3: #1 AWG X 3/8" SINGLE COMP LUG | F3: 1 AWG | G3: EC5-4
A4: WIRE | C4: 241000162 | E4: #1/0 AWG STRANDED WIRE THHN GREEN | F4: #1/0 AWG | G4: JOB
A5: TERMFITT | C5: 241000328 | E5: #1/0 AWG X 1/2" SINGLE COMP LUGS | F5: #1/0 AWG | G5: EC5-4
A6: TERMFITT | C6: 241000164 | E6: #1/0 AWG X 3/8" SINGLE COMPRESSION LUG | F6: 1/0 AWG | G6: EC5-4
A7: FASTENER | B7: 51000105 | D7: HI-COLLAR L/W | E7: #10 HI-COLLAR LOCKWASHER | F7: #10 | G7: MOVE TO CAGE AREA
A8: WIRE | B8: 90459365 | E8: #14 AWG STRANDED WIRE GREEN | F8: 14 AWG | G8: EC-CABINET
A9: WIRE | B9: 50110061 | E9: #14 AWG TFFN RED STRANDED WIRE | F9: #14 AWG | G9: CABINET
A10: WIRE | B10: 50110153 | E10: #14 AWG THHN BLACK STRANDED WIRE | F10: #14 AWG | G10: CABINET
A11: WIRE | B11: 50110062 | E11: #14 AWG THHN WHITE STRANDED WIRE | F11: #14 AWG | G11: CABINET
A12: WIRE | B12: 50110261 | E12: #16 AWG AWG AWG TFFN BLACK STRANDED WIRE | F12: #16 AWG | G12: CABINET
A13: WIRE | B13: 50110266 | E13: #16 AWG AWG TFFN BLUE STRANDED WIRE | F13: #16 AWG | G13: CABINET
A14: WIRE | B14: 50110299 | E14: #16 AWG AWG TFFN GREEN / YELLOW STRIPE STRANDED WIRE | F14: #16 AWG | G14: CABINET
A15: WIRE | B15: 50110264 | E15: #16 AWG AWG TFFN GREEN STRANDED WIRE | F15: #16 AWG | G15: CABINET
A16: WIRE | B16: 50110265 | E16: #16 AWG AWG TFFN GREY STRANDED WIRE | F16: #16 AWG | G16: CABINET
A17: WIRE | B17: 50110262 | E17: #16 AWG AWG TFFN RED STRANDED WIRE | F17: #16 AWG | G17: CABINET
A18: WIRE | B18: 50110300 | E18: #16 AWG AWG TFFN WHITE / BLUE STRIPE STRANDED WIRE | F18: #16 AWG | G18: CABINET
A19: WIRE | B19: 50110263 | E19: #16 AWG AWG TFFN WHITE STRANDED WIRE | F19: #16 AWG | G19: CABINET
A20: WIRE | B20: 50110277 | E20: #16 AWG AWG TFFN YELLOW STRANDED WIRE | F20: #16 AWG | G20: CABINET
A21: TERMFITT | C21: 241000137 | E21: #2 AWG X 1/2" SINGLE COMP LUG | F21: 2 AWG | G21: EC5-4
A22: TERMFITT | C22: 241000136 | E22: #2 AWG X 3/8" SINGLE COMP LUG | F22: 2 AWG | G22: EC5-4 | H22: 20
A23: WIRE | C23: 241000156 | E23: #2 AWG STRANDED WIRE THHN GREEN | F23: #2 AWG | G23: JOB
A24: WIRE | C24: 241000176 | E24: #2 AWG X 3/8" SINGLE COMPRESSION LUG | F24: #2 | G24: JOB
A25: WIRE | B25: 90459367 | E25: #2/0 AWG THHN BLACK STRANDED WIRE | F25: #2/0 AWG | G25: JOB
A26: TERMFITT | C26: 241000138 | E26: #2/0 AWG X 3/8" SINGLE COMP LUG | F26: 2/0 AWG | G26: EC5-4
A27: TERMFITT | C27: 241000351 | E27: #2/0 X 1/2" SINGLE COMPRESION LUG | F27: #2/0 | J27: McMaSTER P/N 6896K17
A28: TERMFITT | C28: 241000140 | E28: #250 MCM X 3/8" SINGLE COMP LUG | F28: 250 MCM | G28: EC5-4
A29: TERMFITT | C29: 241000266 | E29: #3 AWG X 3/8" SINGLE COMP LUG | F29: #400 MCM | G29: EC2-2
A30: WIRE | C30: 241000274 | E30: #3/0 AWG GREEN STRANDED WIRE | F30: #3/0 AWG | G30: JOB
A31: WIRE | C31: 241000274 | E31: #3/0 AWG STRANDED WIRE GREEN | F31: #3/0 AWG | G31: JOB
A32: TERMFITT | C32: 230000493 | E32: #3/0 AWG X 1/2" SINGLE COMP LUG | F32: 3/0 AWG | G32: EC5-5 | J32: MCMASTER P/N 6926K82
A33: TERMFITT | C33: 241000139 | E33: #3/0 AWG X 3/8" SINGLE COMP LUG | F33: 3/0 AWG | G33: EC5-4 | J33: MCMASTER P/N 6926K57
A34: WIRE | B34: 90459379 | E34: #3/0 THHN BLACK STRANDED WIRE | F34: #3/0 AWG | G34: JOB
A35: WIRE | C35: 241000170 | E35: #300 MCM CABLE | F35: #300 MCM | G35: JOB
A36: TERMFITT | C36: 241000272 | E36: #300 MCM X 1/2" SINGLE COMPRESSION LUG | F36: 1/2" | G36: EC5-4
A37: TERMFITT | C37: 241000178 | E37: #300 MCM X 3/8" SINGLE COMPRESSION LUG | F37: #300 MCM | G37: JOB
A38: TERMFITT | C38: 241000275 | E38: #300 MCM X 5/8" SINGLE COMPRESSION LUG | F38: 5/8" | G38: EC5-4
A39: TERMFITT | C39: 241000278 | E39: #350 MCM COMP LUG 5/8" STUD | F39: 5/8" | G39: EC5-4
A40: WIRE | C40: 241000152 | E40: #350 MCM STRANDED WIRE THHN BLACK | F40: #350 MCM | G40: JOB
...
